<?xml version="1.0"?>
<robot name='base_robot' xmlns:xacro="http://www.ros.org/wiki/xacro" >

    <xacro:include filename="$(find multi_robot)/description/gazebo_properties.xacro"/>

    <xacro:arg name="robot_name" default="walle"/>

    <xacro:macro name="base_robot" params="robot_name">  

        <!-- BASE LINK -->
        <link name="base_link"></link>

        <!-- FOOTPRINT LINK -->
        <link name="base_footprint"/>
        <joint name="base_footprint_joint" type="fixed">
            <origin xyz="0 0 0" rpy="0 0 0" />
            <parent link="base_link"/>
            <child link="base_footprint"/>
        </joint>

        <!-- CHASSIS LINK -->
        <link name="chassis">
            <visual>
                <origin xyz="0 0 0" rpy="0 0 0"/>
                <geometry>
                    <mesh filename="file://$(find multi_robot)/meshes/base_link.stl" scale="0.001 0.001 0.001"/>
                </geometry>
              <material name="orange"/>
            </visual>
            <collision>
                <origin xyz="0 0 0" rpy="0 0 0"/>
                <geometry>
                   <mesh filename="file://$(find multi_robot)/meshes/base_link.stl" scale="0.001 0.001 0.001"/>
                </geometry>
            </collision>
            <inertial>
                <origin xyz="0.0021917888767763656 -0.0021761226653942466 0.020287744491421345" rpy="0 0 0"/>
                <mass value="1.6069922534960177"/>
                <inertia ixx="0.001412" iyy="0.001425" izz="0.002705" ixy="-0.0" iyz="0.0" ixz="1.6e-05"/>
            </inertial>
        </link>
        <joint name="chassis_joint" type="fixed">
            <parent link="base_link"/>
            <child link="chassis"/>
            <origin xyz="0.0 0.0 0.0"/>
        </joint>
      
        <!-- RIGHT WHEEL LINK -->
        <link name="right_wheel">
            <visual>
                <origin xyz="0.037242 0.062176 -0.02" rpy="0 0 0"/>
                <geometry>
                    <mesh filename="file://$(find multi_robot)/meshes/wheel_R__1.stl" scale="0.001 0.001 0.001"/>
                </geometry>
                <material name="blue"/>
            </visual>
            <collision>
                <origin xyz="0.037242 0.062176 -0.02" rpy="0 0 0"/>
                <geometry>
                    <mesh filename="file://$(find multi_robot)/meshes/wheel_R__1.stl" scale="0.001 0.001 0.001"/>
                </geometry>
            </collision>
            <inertial>
              <origin xyz="-3.136234283315775e-07 -0.005000122665405275 0.0" rpy="0 0 0"/>
              <mass value="0.09864600932271948"/>
              <inertia ixx="1.1e-05" iyy="2e-05" izz="1.1e-05" ixy="-0.0" iyz="0.0" ixz="0.0"/>
            </inertial>
        </link>
        <joint name="right_wheel_joint" type="continuous">
            <parent link="chassis"/>
            <child link="right_wheel"/>
            <origin xyz="-0.037242 -0.072176 0.02" rpy="0 0 -${pi}"/>
            <axis xyz="0.0 -1.0 0.0"/>
        </joint>

        <!-- RIGHT WHEEL LINK -->
        <link name="left_wheel">
          <visual>
              <origin xyz="0.037242 -0.057824 -0.02" rpy="0 0 0"/>
              <geometry>
                  <mesh filename="file://$(find multi_robot)/meshes/wheel_L_1.stl" scale="0.001 0.001 0.001"/>
              </geometry>
              <material name="blue"/>
          </visual>
          <collision>
              <origin xyz="0.037242 -0.057824 -0.02" rpy="0 0 0"/>
              <geometry>
                  <mesh filename="file://$(find multi_robot)/meshes/wheel_L_1.stl" scale="0.001 0.001 0.001"/>
              </geometry>
          </collision>
          <inertial>
              <origin xyz="-3.136234283523942e-07 0.004999877334594713 -3.469446951953614e-18" rpy="0 0 0"/>
              <mass value="0.0986460093227195"/>
              <inertia ixx="1.1e-05" iyy="2e-05" izz="1.1e-05" ixy="0.0" iyz="0.0" ixz="0.0"/>
          </inertial>
        </link>
        <joint name="left_wheel_joint" type="continuous">
            <parent link="chassis"/>
            <child link="left_wheel"/>
            <origin xyz="-0.037242 0.057824 0.02" rpy="0 ${pi/2} -${2*pi}"/>
            <axis xyz="-0.0 1.0 0.0"/>
        </joint>

        <!-- CASTER WHEEL LINK -->
        <link name="caster_wheel">
            <visual>
                <origin xyz="-0.042758 0.002176 -0.005" rpy="0 0 0"/>
                <geometry>
                    <mesh filename="file://$(find multi_robot)/meshes/caster_wheel_1.stl" scale="0.001 0.001 0.001"/>
                </geometry>
                <material name="blue"/>
            </visual>
            <collision>
                <origin xyz="-0.042758 0.002176 -0.005" rpy="0 0 0"/>
                <geometry>
                    <mesh filename="file://$(find multi_robot)/meshes/caster_wheel_1.stl" scale="0.001 0.001 0.001"/>
                </geometry>
            </collision>     
            <inertial>
                <origin xyz="-3.136234283454553e-07 -1.2266540526644637e-07 -0.001874999999999999" rpy="0 0 0"/>
                <mass value="0.002055125194223321"/>
                <inertia ixx="0.0" iyy="0.0" izz="0.0" ixy="0.0" iyz="-0.0" ixz="0.0"/>
            </inertial>
        </link>
        <joint name="caster_wheel_joint" type="fixed">
          <parent link="chassis"/>
          <child link="caster_wheel"/>
          <origin xyz="0.042758 -0.002176 0.005" rpy="0 0 0"/>
        </joint>

        <!-- SIMULATION DETAILS -->
        <xacro:walle_sim robot_name="$(arg robot_name)"/>
    </xacro:macro>

</robot>